Workbook
Name Slicer_Clean_Status: #N/A
Name Slicer_Payment_Method: #N/A

Sheet Executive Dashboard
B1: FRAUD ANALYTICS OVERVIEW
B2: TOTAL AUDITED DATASET | E2: GROSS TRANSACTION REVENUE | H2: TOTAL PIPELINE AT RISK | K2: ACTIVE DISPUTE INSTANCES
B5: =COUNTA('Orders Ledger'!A2:A1501) -> 1500 | E5: =SUM('Orders Ledger'!N2:N1501) -> 1338115.2 | H5: =SUMIFS('Orders Ledger'!N:N, 'Orders Ledger'!J:J, "disputed") + SUMIFS('Orders Ledger'!N:N, 'Orders Ledger'!J:J, "PENDING_REVIEW") -> 667317.77 | K5: =COUNTIF('Orders Ledger'!J:J, "disputed") -> 190
A19: CRITICAL HOLDS QUEUE
A20: {=IFERROR(_xlfn.XLOOKUP("Grand Total", Pivot!$B$36:$B$46, _xlfn.XLOOKUP("PENDING_REVIEW", Pivot!$36:$36, Pivot!$36:$46)), 0)} -> 183
A22: SLA BREACH STATUS
A23: =IF(A20>150, "🔴 REVIEW SLA OVERRUN", "🟢 SAFE QUEUE LEVEL") -> 🔴 REVIEW SLA OVERRUN
A26: THREAT EXP VELOCITY | I26: Order_ID | J26: Customer_ID | K26: Category | L26: Device_Used | M26: Sum of Total_Revenue
I27: ORD100160 | J27: CUST-1094 | K27: Luxury Goods | L27: Desktop | M27: 9401.8
A28: Automated Bots | I28: ORD100282 | J28: CUST-1206 | K28: Luxury Goods | L28: Bot_Server | M28: 9954.6
A29: =IFERROR(_xlfn.XLOOKUP("disputed", Pivot!$36:$36, Pivot!$37:$37) / _xlfn.XLOOKUP("Grand Total", Pivot!$36:$36, Pivot!$37:$37), 0) -> 0.28708134 | I29: ORD100414 | J29: CUST-1125 | K29: Luxury Goods | L29: Bot_Server | M29: 11683.4
A30: Cross-Border | I30: ORD100512 | J30: CUST-1134 | K30: Luxury Goods | L30: Desktop | M30: 9346.72
A31: =IFERROR(_xlfn.XLOOKUP("disputed", Pivot!$36:$36, Pivot!$40:$40) / _xlfn.XLOOKUP("Grand Total", Pivot!$36:$36, Pivot!$40:$40), 0) -> 0.28502415 | I31: ORD100571 | J31: CUST-1170 | K31: Luxury Goods | L31: Desktop | M31: 11683.4
I32: ORD100636 | J32: CUST-1166 | K32: Luxury Goods | L32: Mobile_Emulator | M32: 9346.72
I33: ORD100778 | J33: CUST-1036 | K33: Luxury Goods | L33: Desktop | M33: 9401.8
I34: ORD101105 | J34: CUST-1139 | K34: Luxury Goods | L34: Desktop | M34: 9376.2
I35: ORD101126 | J35: CUST-1164 | K35: Luxury Goods | L35: Mobile_Emulator | M35: 9954.6
I36: ORD101133 | J36: CUST-1218 | K36: Luxury Goods | L36: Desktop | M36: 9376.2
I37: ORD101167 | J37: CUST-1070 | K37: Luxury Goods | L37: Desktop | M37: 9401.8
I38: ORD101394 | J38: CUST-1242 | K38: Luxury Goods | L38: Bot_Server | M38: 9346.72
I39: ORD101450 | J39: CUST-1265 | K39: Luxury Goods | L39: Bot_Server | M39: 9346.72
I40: ORD101476 | J40: CUST-1162 | K40: Luxury Goods | L40: Mobile_Emulator | M40: 9346.72
I41: Grand Total | M41: 136967.4

Sheet Orders Ledger
A1: Order_ID | B1: Customer_ID | C1: Product_SKU | D1: Quantity | E1: Order_Timestamp | F1: Payment_Method | G1: Order_Country | H1: Device_Used | I1: Raw_Status | J1: Clean_Status | K1: Product_Name | L1: Category | M1: Unit_Price | N1: Total_Revenue
A2: ORD100000 | B2: CUST-1129 | C2: PROD-ELEC-057 | D2: 1 | E2: 45796.799 | F2: Digital_Wallet | G2: Canada | H2: Mobile_App | I2: delivered | J2: =TRIM(I2) -> delivered | K2: =_xlfn.XLOOKUP(C2, 'Product Catalog'!$A:$A, 'Product Catalog'!$B:$B, "Unknown Product") -> Keyboard Model F57 | L2: =_xlfn.XLOOKUP(C2, 'Product Catalog'!$A:$A, 'Product Catalog'!$C:$C, "Unknown Category") -> Electronics | M2: =_xlfn.XLOOKUP(C2, 'Product Catalog'!$A:$A, 'Product Catalog'!$D:$D, 0) -> 60.02 | N2: =D2 * M2 -> 60.02
A3: ORD100001 | B3: CUST-1041 | C3: PROD-APPA-137 | D3: 1 | E3: 46014.386 | F3: Credit_Card | G3: United Kingdom | H3: Mobile_App | I3: delivered | J3: =TRIM(I3) -> delivered | K3: =_xlfn.XLOOKUP(C3, 'Product Catalog'!$A:$A, 'Product Catalog'!$B:$B, "Unknown Product") -> Sneakers Model H137 | L3: =_xlfn.XLOOKUP(C3, 'Product Catalog'!$A:$A, 'Product Catalog'!$C:$C, "Unknown Category") -> Apparel | M3: =_xlfn.XLOOKUP(C3, 'Product Catalog'!$A:$A, 'Product Catalog'!$D:$D, 0) -> 33.53 | N3: =D3 * M3 -> 33.53
A4: ORD100002 | B4: CUST-1240 | C4: PROD-ELEC-078 | D4: 1 | E4: 45728.155 | F4: Digital_Wallet | G4: United Kingdom | H4: Mobile_Web | I4: delivered | J4: =TRIM(I4) -> delivered | K4: =_xlfn.XLOOKUP(C4, 'Product Catalog'!$A:$A, 'Product Catalog'!$B:$B, "Unknown Product") -> Mouse Model A78 | L4: =_xlfn.XLOOKUP(C4, 'Product Catalog'!$A:$A, 'Product Catalog'!$C:$C, "Unknown Category") -> Electronics | M4: =_xlfn.XLOOKUP(C4, 'Product Catalog'!$A:$A, 'Product Catalog'!$D:$D, 0) -> 141.34 | N4: =D4 * M4 -> 141.34
A5: ORD100003 | B5: CUST-1009 | C5: PROD-DIGI-053 | D5: 1 | E5: 45973.834 | F5: Credit_Card | G5: United Kingdom | H5: Mobile_Web | I5: delivered | J5: =TRIM(I5) -> delivered | K5: =_xlfn.XLOOKUP(C5, 'Product Catalog'!$A:$A, 'Product Catalog'!$B:$B, "Unknown Product") -> Premium Stream 1M Model B53 | L5: =_xlfn.XLOOKUP(C5, 'Product Catalog'!$A:$A, 'Product Catalog'!$C:$C, "Unknown Category") -> Digital Services | M5: =_xlfn.XLOOKUP(C5, 'Product Catalog'!$A:$A, 'Product Catalog'!$D:$D, 0) -> 13.87 | N5: =D5 * M5 -> 13.87
A6: ORD100004 | B6: CUST-1276 | C6: PROD-DIGI-131 | D6: 1 | E6: 45780.344 | F6: Credit_Card | G6: United States | H6: Mobile_App | I6: SHIPPED | J6: =TRIM(I6) -> SHIPPED | K6: =_xlfn.XLOOKUP(C6, 'Product Catalog'!$A:$A, 'Product Catalog'!$B:$B, "Unknown Product") -> VPN 6-Month Pass Model B131 | L6: =_xlfn.XLOOKUP(C6, 'Product Catalog'!$A:$A, 'Product Catalog'!$C:$C, "Unknown Category") -> Digital Services | M6: =_xlfn.XLOOKUP(C6, 'Product Catalog'!$A:$A, 'Product Catalog'!$D:$D, 0) -> 46.92 | N6: =D6 * M6 -> 46.92
A7: ORD100005 | B7: CUST-1026 | C7: PROD-HOME-074 | D7: 1 | E7: 45683.952 | F7: Digital_Wallet | G7: United States | H7: Mobile_Web | I7: SHIPPED | J7: =TRIM(I7) -> SHIPPED | K7: =_xlfn.XLOOKUP(C7, 'Product Catalog'!$A:$A, 'Product Catalog'!$B:$B, "Unknown Product") -> Blender Model W74 | L7: =_xlfn.XLOOKUP(C7, 'Product Catalog'!$A:$A, 'Product Catalog'!$C:$C, "Unknown Category") -> Home Goods | M7: =_xlfn.XLOOKUP(C7, 'Product Catalog'!$A:$A, 'Product Catalog'!$D:$D, 0) -> 127.16 | N7: =D7 * M7 -> 127.16
A8: ORD100006 | B8: CUST-1179 | C8: PROD-DIGI-073 | D8: 4 | E8: 45929.321 | F8: Crypto_Proxy | G8: Unknown Blacklisted Zone | H8: Desktop | I8: PENDING_REVIEW | J8: =TRIM(I8) -> PENDING_REVIEW | K8: =_xlfn.XLOOKUP(C8, 'Product Catalog'!$A:$A, 'Product Catalog'!$B:$B, "Unknown Product") -> VPN 6-Month Pass Model V73 | L8: =_xlfn.XLOOKUP(C8, 'Product Catalog'!$A:$A, 'Product Catalog'!$C:$C, "Unknown Category") -> Digital Services | M8: =_xlfn.XLOOKUP(C8, 'Product Catalog'!$A:$A, 'Product Catalog'!$D:$D, 0) -> 58.13 | N8: =D8 * M8 -> 232.52
A9: ORD100007 | B9: CUST-1114 | C9: PROD-APPA-091 | D9: 1 | E9: 45984.331 | F9: Credit_Card | G9: France | H9: Mobile_App | I9: delivered | J9: =TRIM(I9) -> delivered | K9: =_xlfn.XLOOKUP(C9, 'Product Catalog'!$A:$A, 'Product Catalog'!$B:$B, "Unknown Product") -> Jacket Model N91 | L9: =_xlfn.XLOOKUP(C9, 'Product Catalog'!$A:$A, 'Product Catalog'!$C:$C, "Unknown Category") -> Apparel | M9: =_xlfn.XLOOKUP(C9, 'Product Catalog'!$A:$A, 'Product Catalog'!$D:$D, 0) -> 13.96 | N9: =D9 * M9 -> 13.96
A10: ORD100008 | B10: CUST-1035 | C10: PROD-DIGI-076 | D10: 1 | E10: 45684.142 | F10: Credit_Card | G10: High-Risk Country Proxy | H10: Mobile_Emulator | I10: PENDING_REVIEW | J10: =TRIM(I10) -> PENDING_REVIEW | K10: =_xlfn.XLOOKUP(C10, 'Product Catalog'!$A:$A, 'Product Catalog'!$B:$B, "Unknown Product") -> E-Book Access Model Y76 | L10: =_xlfn.XLOOKUP(C10, 'Product Catalog'!$A:$A, 'Product Catalog'!$C:$C, "Unknown Category") -> Digital Services | M10: =_xlfn.XLOOKUP(C10, 'Product Catalog'!$A:$A, 'Product Catalog'!$D:$D, 0) -> 92.33 | N10: =D10 * M10 -> 92.33
A11: ORD100009 | B11: CUST-1020 | C11: PROD-ELEC-021 | D11: 5 | E11: 45869.469 | F11: Credit_Card | G11: Unknown Blacklisted Zone | H11: Bot_Server | I11: cancelled | J11: =TRIM(I11) -> cancelled | K11: =_xlfn.XLOOKUP(C11, 'Product Catalog'!$A:$A, 'Product Catalog'!$B:$B, "Unknown Product") -> Keyboard Model V21 | L11: =_xlfn.XLOOKUP(C11, 'Product Catalog'!$A:$A, 'Product Catalog'!$C:$C, "Unknown Category") -> Electronics | M11: =_xlfn.XLOOKUP(C11, 'Product Catalog'!$A:$A, 'Product Catalog'!$D:$D, 0) -> 208.12 | N11: =D11 * M11 -> 1040.6
A12: ORD100010 | B12: CUST-1015 | C12: PROD-LUXU-025 | D12: 5 | E12: 45899.142 | F12: Crypto_Proxy | G12: France | H12: Mobile_Emulator | I12: PENDING_REVIEW | J12: =TRIM(I12) -> PENDING_REVIEW | K12: =_xlfn.XLOOKUP(C12, 'Product Catalog'!$A:$A, 'Product Catalog'!$B:$B, "Unknown Product") -> Silk Scarf Model Z25 | L12: =_xlfn.XLOOKUP(C12, 'Product Catalog'!$A:$A, 'Product Catalog'!$C:$C, "Unknown Category") -> Luxury Goods | M12: =_xlfn.XLOOKUP(C12, 'Product Catalog'!$A:$A, 'Product Catalog'!$D:$D, 0) -> 878.03 | N12: =D12 * M12 -> 4390.15
A13: ORD100011 | B13: CUST-1126 | C13: PROD-ELEC-012 | D13: 2 | E13: 46006.195 | F13: Credit_Card | G13: France | H13: Desktop | I13: SHIPPED | J13: =TRIM(I13) -> SHIPPED | K13: =_xlfn.XLOOKUP(C13, 'Product Catalog'!$A:$A, 'Product Catalog'!$B:$B, "Unknown Product") -> Cable Model M12 | L13: =_xlfn.XLOOKUP(C13, 'Product Catalog'!$A:$A, 'Product Catalog'!$C:$C, "Unknown Category") -> Electronics | M13: =_xlfn.XLOOKUP(C13, 'Product Catalog'!$A:$A, 'Product Catalog'!$D:$D, 0) -> 83.9 | N13: =D13 * M13 -> 167.8
... A1501: ORD101499 | B1501: CUST-1275 | C1501: PROD-HOME-016 | D1501: 1 | E1501: 45922.358 | F1501: Credit_Card | G1501: United States | H1501: Desktop | I1501: delivered | J1501: =TRIM(I1501) -> delivered | K1501: =_xlfn.XLOOKUP(C1501, 'Product Catalog'!$A:$A, 'Product Catalog'!$B:$B, "Unknown Product") -> Blender Model Q16 | L1501: =_xlfn.XLOOKUP(C1501, 'Product Catalog'!$A:$A, 'Product Catalog'!$C:$C, "Unknown Category") -> Home Goods | M1501: =_xlfn.XLOOKUP(C1501, 'Product Catalog'!$A:$A, 'Product Catalog'!$D:$D, 0) -> 79.23 | N1501: =D1501 * M1501 -> 79.23

Sheet Product Catalog
A1: Product_SKU | B1: Product_Name | C1: Category | D1: Unit_Price | E1: Shipping_Requirement | F1: Merchant_Reputation_Score
A2: PROD-ELEC-001 | B2: Mouse Model B1 | C2: Electronics | D2: 189.26 | E2: Standard Physical | F2: 2.4
A3: PROD-APPA-002 | B3: Sneakers Model C2 | C3: Apparel | D3: 21.27 | E3: Standard Physical | F3: 4.1
A4: PROD-LUXU-003 | B4: Designer Watch Model D3 | C4: Luxury Goods | D4: 1599.08 | E4: Special Handling Required | F4: 1.6
A5: PROD-ELEC-004 | B5: Keyboard Model E4 | C5: Electronics | D5: 69.68 | E5: Standard Physical | F5: 3.6
A6: PROD-LUXU-005 | B6: Leather Handbag Model F5 | C6: Luxury Goods | D6: 1875.24 | E6: Special Handling Required | F6: 4
A7: PROD-DIGI-006 | B7: Premium Stream 1M Model G6 | C7: Digital Services | D7: 47.23 | E7: Digital (Instant) | F7: 2.5
A8: PROD-ELEC-007 | B8: Smartwatch Model H7 | C8: Electronics | D8: 204.37 | E8: Standard Physical | F8: 3.9
A9: PROD-HOME-008 | B9: Toaster Model I8 | C9: Home Goods | D9: 44.88 | E9: Standard Physical | F9: 4.9
A10: PROD-HOME-009 | B10: Coffee Maker Model J9 | C10: Home Goods | D10: 34.84 | E10: Standard Physical | F10: 1.8
A11: PROD-HOME-010 | B11: Desk Lamp Model K10 | C11: Home Goods | D11: 62.32 | E11: Standard Physical | F11: 1.7
A12: PROD-DIGI-011 | B12: VPN 6-Month Pass Model L11 | C12: Digital Services | D12: 16.73 | E12: Digital (Instant) | F12: 4.7
A13: PROD-ELEC-012 | B13: Cable Model M12 | C13: Electronics | D13: 83.9 | E13: Standard Physical | F13: 3.7
... A151: PROD-DIGI-150 | B151: E-Book Access Model U150 | C151: Digital Services | D151: 75.69 | E151: Digital (Instant) | F151: 4.4

Sheet Pivot
B5: Category | C5: Sum of Total_Revenue
B6: Apparel | C6: 30888.91
B7: Digital Services | C7: 29011.85
B8: Electronics | C8: 85098.23
B9: Home Goods | C9: 52396.01
B10: Luxury Goods | C10: 1140720.2
B11: Grand Total | C11: 1338115.2
B20: Order_Country | C20: Count of Order_ID
B21: Canada | C21: 204
B22: France | C22: 230
B23: Germany | C23: 203
B24: High-Risk Country Proxy | C24: 210
B25: United Kingdom | C25: 192
B26: United States | C26: 238
B27: Unknown Blacklisted Zone | C27: 223
B28: Grand Total | C28: 1500
B35: Order_ID | C35: Clean_Status
B36: Device_Used | C36: cancelled | D36: delivered | E36: disputed | F36: PENDING_REVIEW | G36: REFUNDED | H36: SHIPPED | I36: Grand Total
B37: Bot_Server | C37: 49 | E37: 60 | F37: 41 | G37: 59 | I37: 209
B38: Desktop | C38: 48 | D38: 274 | E38: 60 | F38: 80 | G38: 78 | H38: 29 | I38: 569
B39: Mobile_App | C39: 12 | D39: 279 | E39: 9 | F39: 10 | G39: 13 | H39: 46 | I39: 369
B40: Mobile_Emulator | C40: 61 | E40: 59 | F40: 45 | G40: 42 | I40: 207
B41: Mobile_Web | C41: 8 | D41: 109 | E41: 2 | F41: 7 | G41: 4 | H41: 16 | I41: 146
B42: Grand Total | C42: 178 | D42: 662 | E42: 190 | F42: 183 | G42: 196 | H42: 91 | I42: 1500
I48: Clean_Status | J48: (All)
I50: Row Labels | J50: Count of Order_ID
I51: Jan | J51: 138
I52: Feb | J52: 119
I53: Mar | J53: 139
I54: Apr | J54: 120
I55: May | J55: 120
I56: Jun | J56: 120
I57: Jul | J57: 144
B58: Order ID | C58: Customer ID | D58: Order Country | E58: Device Used | F58: Payment Method | G58: Total Revenue | I58: Aug | J58: 119
B59: {=IFERROR(INDEX('Orders Ledger'!$A$2:$A$1501, SMALL(IF(('Orders Ledger'!$J$2:$J$1501="disputed")+('Orders Ledger'!$J$2:$J$1501="PENDING_REVIEW"), ROW('Orders Ledger'!$A$2:$A$1501)-ROW('Orders Ledger'!$A$2)+1), ROW(1:1))), "")} -> ORD100006 | C59: =IF(B59="","",_xlfn.XLOOKUP(B59,'Orders Ledger'!$A:$A,'Orders Ledger'!$B:$B,"")) -> CUST-1179 | D59: =IF(B59="","",_xlfn.XLOOKUP(B59,'Orders Ledger'!$A:$A,'Orders Ledger'!$G:$G,"")) -> Unknown Blacklisted Zone | E59: =IF(B59="","",_xlfn.XLOOKUP(B59,'Orders Ledger'!$A:$A,'Orders Ledger'!$H:$H,"")) -> Desktop | F59: =IF(B59="","",_xlfn.XLOOKUP(B59,'Orders Ledger'!$A:$A,'Orders Ledger'!$F:$F,"")) -> Crypto_Proxy | G59: =IF(B59="","",_xlfn.XLOOKUP(B59,'Orders Ledger'!$A:$A,'Orders Ledger'!$N:$N,0)) -> 232.52 | I59: Sep | J59: 100
B60: {=IFERROR(INDEX('Orders Ledger'!$A$2:$A$1501, SMALL(IF(('Orders Ledger'!$J$2:$J$1501="disputed")+('Orders Ledger'!$J$2:$J$1501="PENDING_REVIEW"), ROW('Orders Ledger'!$A$2:$A$1501)-ROW('Orders Ledger'!$A$2)+1), ROW(2:2))), "")} -> ORD100008 | C60: =IF(B60="","",_xlfn.XLOOKUP(B60,'Orders Ledger'!$A:$A,'Orders Ledger'!$B:$B,"")) -> CUST-1035 | D60: =IF(B60="","",_xlfn.XLOOKUP(B60,'Orders Ledger'!$A:$A,'Orders Ledger'!$G:$G,"")) -> High-Risk Country Proxy | E60: =IF(B60="","",_xlfn.XLOOKUP(B60,'Orders Ledger'!$A:$A,'Orders Ledger'!$H:$H,"")) -> Mobile_Emulator | F60: =IF(B60="","",_xlfn.XLOOKUP(B60,'Orders Ledger'!$A:$A,'Orders Ledger'!$F:$F,"")) -> Credit_Card | G60: =IF(B60="","",_xlfn.XLOOKUP(B60,'Orders Ledger'!$A:$A,'Orders Ledger'!$N:$N,0)) -> 92.33 | I60: Oct | J60: 147
B61: {=IFERROR(INDEX('Orders Ledger'!$A$2:$A$1501, SMALL(IF(('Orders Ledger'!$J$2:$J$1501="disputed")+('Orders Ledger'!$J$2:$J$1501="PENDING_REVIEW"), ROW('Orders Ledger'!$A$2:$A$1501)-ROW('Orders Ledger'!$A$2)+1), ROW(3:3))), "")} -> ORD100010 | C61: =IF(B61="","",_xlfn.XLOOKUP(B61,'Orders Ledger'!$A:$A,'Orders Ledger'!$B:$B,"")) -> CUST-1015 | D61: =IF(B61="","",_xlfn.XLOOKUP(B61,'Orders Ledger'!$A:$A,'Orders Ledger'!$G:$G,"")) -> France | E61: =IF(B61="","",_xlfn.XLOOKUP(B61,'Orders Ledger'!$A:$A,'Orders Ledger'!$H:$H,"")) -> Mobile_Emulator | F61: =IF(B61="","",_xlfn.XLOOKUP(B61,'Orders Ledger'!$A:$A,'Orders Ledger'!$F:$F,"")) -> Crypto_Proxy | G61: =IF(B61="","",_xlfn.XLOOKUP(B61,'Orders Ledger'!$A:$A,'Orders Ledger'!$N:$N,0)) -> 4390.15 | I61: Nov | J61: 111
B62: {=IFERROR(INDEX('Orders Ledger'!$A$2:$A$1501, SMALL(IF(('Orders Ledger'!$J$2:$J$1501="disputed")+('Orders Ledger'!$J$2:$J$1501="PENDING_REVIEW"), ROW('Orders Ledger'!$A$2:$A$1501)-ROW('Orders Ledger'!$A$2)+1), ROW(4:4))), "")} -> ORD100025 | C62: =IF(B62="","",_xlfn.XLOOKUP(B62,'Orders Ledger'!$A:$A,'Orders Ledger'!$B:$B,"")) -> CUST-1058 | D62: =IF(B62="","",_xlfn.XLOOKUP(B62,'Orders Ledger'!$A:$A,'Orders Ledger'!$G:$G,"")) -> Unknown Blacklisted Zone | E62: =IF(B62="","",_xlfn.XLOOKUP(B62,'Orders Ledger'!$A:$A,'Orders Ledger'!$H:$H,"")) -> Mobile_Emulator | F62: =IF(B62="","",_xlfn.XLOOKUP(B62,'Orders Ledger'!$A:$A,'Orders Ledger'!$F:$F,"")) -> Digital_Wallet | G62: =IF(B62="","",_xlfn.XLOOKUP(B62,'Orders Ledger'!$A:$A,'Orders Ledger'!$N:$N,0)) -> 574.55 | I62: Dec | J62: 123
B63: {=IFERROR(INDEX('Orders Ledger'!$A$2:$A$1501, SMALL(IF(('Orders Ledger'!$J$2:$J$1501="disputed")+('Orders Ledger'!$J$2:$J$1501="PENDING_REVIEW"), ROW('Orders Ledger'!$A$2:$A$1501)-ROW('Orders Ledger'!$A$2)+1), ROW(5:5))), "")} -> ORD100029 | C63: =IF(B63="","",_xlfn.XLOOKUP(B63,'Orders Ledger'!$A:$A,'Orders Ledger'!$B:$B,"")) -> CUST-1296 | D63: =IF(B63="","",_xlfn.XLOOKUP(B63,'Orders Ledger'!$A:$A,'Orders Ledger'!$G:$G,"")) -> High-Risk Country Proxy | E63: =IF(B63="","",_xlfn.XLOOKUP(B63,'Orders Ledger'!$A:$A,'Orders Ledger'!$H:$H,"")) -> Mobile_Emulator | F63: =IF(B63="","",_xlfn.XLOOKUP(B63,'Orders Ledger'!$A:$A,'Orders Ledger'!$F:$F,"")) -> Digital_Wallet | G63: =IF(B63="","",_xlfn.XLOOKUP(B63,'Orders Ledger'!$A:$A,'Orders Ledger'!$N:$N,0)) -> 878.03 | I63: Grand Total | J63: 1500
B64: {=IFERROR(INDEX('Orders Ledger'!$A$2:$A$1501, SMALL(IF(('Orders Ledger'!$J$2:$J$1501="disputed")+('Orders Ledger'!$J$2:$J$1501="PENDING_REVIEW"), ROW('Orders Ledger'!$A$2:$A$1501)-ROW('Orders Ledger'!$A$2)+1), ROW(6:6))), "")} -> ORD100033 | C64: =IF(B64="","",_xlfn.XLOOKUP(B64,'Orders Ledger'!$A:$A,'Orders Ledger'!$B:$B,"")) -> CUST-1192 | D64: =IF(B64="","",_xlfn.XLOOKUP(B64,'Orders Ledger'!$A:$A,'Orders Ledger'!$G:$G,"")) -> High-Risk Country Proxy | E64: =IF(B64="","",_xlfn.XLOOKUP(B64,'Orders Ledger'!$A:$A,'Orders Ledger'!$H:$H,"")) -> Desktop | F64: =IF(B64="","",_xlfn.XLOOKUP(B64,'Orders Ledger'!$A:$A,'Orders Ledger'!$F:$F,"")) -> Credit_Card | G64: =IF(B64="","",_xlfn.XLOOKUP(B64,'Orders Ledger'!$A:$A,'Orders Ledger'!$N:$N,0)) -> 34.84
...
